Workbook
Name °CARNE.lanche: Porções!$B$221:$B$231
Name °LEITE.LIGHT: Porções!$B$79:$B$89
Name °QUEIJO.light: Porções!$B$99:$B$109
Name °SUCO.light: Porções!$B$146:$B$152
Name CARBOIDRATO: Porções!$B$2:$B$65
Name EVENTUAL: Porções!$B$306:$B$312
Name Frases: Formulas!$A$1:$A$10
Name FRUTA: Porções!$B$111:$B$136
Name GORDURA: Porções!$B$254:$B$268
Name GRUPOS: Formulas!$C$2:$C$20
Name LEGUME: Porções!$B$188:$B$204
Name LEGUMINOSA: Porções!$B$233:$B$238
Name LEITE: Porções!$B$66:$B$77
Name OUTROS: Porções!$B$270:$B$279
Name PASTASºPATÊS: Porções!$B$91:$B$97
Name PROTEÍNA: Porções!$B$206:$B$219
Name SEMENTESºFARELOS: Porções!$B$240:$B$252
Name SUCO: Porções!$B$138:$B$144
Name SUPLEMENTOS: Porções!$B$281:$B$304
Name VERDURA: Porções!$B$154:$B$186

Sheet QPC
A1: Qual o seu nome completo? | B1: CPF | C1: data de nascimento | D1: Qual o numero do seu telefone (WhatsApp)? | E1: Qual o seu e-mail? | F1: Qual o seu objetivo em relação a consulta? | G1: Qual a sua profissão/estudos/rotina? | H1: Utiliza algum medicamento? Qual? | I1: Utiliza algum suplemento/vitaminas? Qual? | J1: Tem histórico na família de alguma doença? | K1: Já fez alguma cirurgia? | L1: Sinais e sintomas | M1: Idade | N1: Possui marca-passo ou outro dispositivo médico implantado? | O1: Como você avaliaria sua qualidade de vida? Dê uma nota de 1 a 5. | P1: O quanto você está satisfeito(a) com a sua aparência física? Dê uma nota de 1 a 5. | Q1: Em sua opinião, quais os principais limitadores (que dificultam ou impedem) o seu Emagrecimento ou Mudança de Hábito Alimentar? | R1: Como você acha que eu posso ajudá-la (o) a atingir seus objetivos? | S1: De 0 a 10 quanto você está comprometido(a) a iniciar o tratamento para atingir os seus objetivos? | T1: Possui diagnóstico de alguma doença? | U1: Qual é o seu aliemento favorito? | V1: O que não gosta ? | W1: Toma refrigerante? | X1: Consome bebida alcolica? | Y1: Quantos litros de água? | Z1: Cigarro ou outros? | AA1: Consome sucos? | AB1: Consome chás? | AC1: Lanches, pizzas, cachorro quente? | AD1: Água de coco?

Sheet Informações gerais
A2: CADASTRO PACIENTE | B2: Data:
A3: Nome: | B3: =QPC!A2 -> 0
A4: Idade: | B4: =QPC!M2 -> 0
A5: Data de Nascimento: | B5: =QPC!C2 -> 0
A6: Telefone/whats: | B6: =QPC!D2 -> 0
A7: Email: | B7: =QPC!E2 -> 0
A8: Profissão/estudo: | B8: =QPC!G2 -> 0
A9: Motivo principal da consulta: | B9: =QPC!F2 -> 0
A10: CPF: | B10: =QPC!B2 -> 0
A11: Já foi em algum nutricionista:
A12: Alguem indicou:
A13: Como você avaliaria sua qualidade de vida? Dê uma nota de 1 a 5. | B13: =QPC!O2 -> 0
A14: O quanto você está satisfeito(a) com a sua aparência física? Dê uma nota de 1 a 5. | B14: =QPC!P2 -> 0
A15: Como você acha que eu posso ajudá-la (o) a atingir seus objetivos? | B15: =QPC!R2 -> 0
A16: De 0 a 10 quanto você está comprometido (a) a iniciar o tratamento para atingir os seus objetivos? | B16: =QPC!S2 -> 0
A17: Em sua opinião, quais os principais limitadores (que dificultam ou impedem) o seu Emagrecimento ou Mudança de Hábito Alimentar? | B17: =QPC!Q2 -> 0
A19: HISTÓRIA CLÍNICA
A20: Antecedentes familiares: | B20: =QPC!J2 -> 0
A21: Diagnóstico de alguma doença: | B21: =QPC!T2 -> 0
A22: Cirurgias: | B22: =QPC!K2 -> 0
A23: Dispositivo médico/marca-passo | B23: =QPC!N2 -> 0
A24: Uso de medicamentos: | B24: =QPC!H2 -> 0
A25: Uso de suplementos: | B25: =QPC!I2 -> 0
A26: Mulher anticoncepcional:
A27: Intolerâncias:
A28: Alergia alimentar:
A29: Bebidas alcoólicas: | B29: =QPC!X2 -> 0
A30: Tabagismo: | B30: =QPC!Z2 -> 0
A31: Horas de sono/dia:
A32: Atividade física:
A33: Hábito intestinal:
A34: Consistência das fezes:
A35: Cor da urina:
A36: Unhas:
A37: Lingua: se branca (disbiose, má digestão) se seborreica amarelada (disturbios hepaticos, ver as enzimas hepaticas, ver sindrome metabolica) lingua com rachaduras
A38: Observações:
A46: ALT + ENTER PARA DESCER
A47: EVOLUÇÃO

Sheet Sinais e sintomas 
A1: SINAIS E SINTOMAS | H1: DATA | I1: DATA | J1: DATA | K1: DATA | L1: DATA | M1: DATA | N1: DATA | O1: DATA | P1: DATA | Q1: DATA
A2: CABEÇA | B2: Dor de cabeça
B3: Sensação de desmaio
B4: Tonturas
B5: Insônia
A6: OLHOS | B6: Lacrimejantes ou coçando
B7: Inchados, vermelhos ou com cílios colando
B8: Bolsas ou olheiras abaixo dos olhos
B9: Visão borrada ou em túnel
A10: OUVIDOS | B10: Coceira
B11: Dores de ouvido, infecções auditivas
A12: NARIZ | B12: Entupido
B13: Sinusite
B14: Rinite
B15: Excessiva formação de muco
A16: BOCA E GARGANTA | B16: Dificuldade com mastigação ou deglutição
B17: Herpes labial
B18: Língua, gengivas ou lábios inchados/ descoloridos
B19: Aftas
A20: PELE | B20: Acne (espinhas)
B21: Feridas que coçam, erupções ou pele seca
B22: Perda de cabelo
B23: Dermatite
B24: Suor excessivo
A25: CORAÇÃO | B25: Batidas irregulares ou falhando
B26: Batidas rápidas de mais
B27: Dor no peito
A28: PULMÕES | B28: Asma, bronquite
B29: Dificuldade para respirar
A30: TRATO DIGESTIVO | B30: Náuseas, vômitos
B31: Diarreia
B32: Constipação/ prisão de ventre
B33: Sente-se inchado/ abdômen distendido
B34: Gases intestinais
B35: Azia
B36: Dor estomacal/ intestinal
A37: ARTICULAÇÕES MÚSCULOS | B37: Dores articulares
B38: Artrite/artrose
B39: Dores musculares/ câimbras
A40: ENERGIA E ATIVIDADE | B40: Fadiga/ moleza
...

Sheet Exames 
A1: EXAMES LABORATORIAIS
A2: PARÂMETROS | B2: VALORES DE REFERÊNCIA | C2: DATA
A3: Hemácias | B3: 4,5 – 5,5 mil/mm3 se estiver baixa pode ser anemia, se estiver alta pode ser hipoxia por tabagismo, apneia do sono, pessoas q moram em lugar alto Hipoxia é qd o corpo passa dificulade de levar o oxigenio para as celulas, ai o corpo aumenta mais hemacias para dar conta. Excesso de testo tbm aumenta hemacias
A4: Hemoglobina | B4: 12,0 – 16,5 g/dL menor que 12 é anemia agora tem que ver o VCM e ver do que é essa anemia. Inflamação tbm diminui hemoglobina.
A5: Hematócrito | B5: 40,0 – 50,0 % se abaixo de 33 para mulheres e abaixo de 36 para homens é conversão de T4 para T3 reverso, o que é ruim, nesse caso o organismo está poupando energia. Hematocrito mt mt alto pode ser desidratação
A6: VCM | B6: 88 – 92 fL menor de 80 microcitica , relação com talassemia falta de ferro , falta de cobre e quando ta alto é macrocitica falta de B9 e B12 ou até hepatopatia hemoglobina baixa c VCM normal pode ser inicio de uma anemia, doença renal, hipotireoidismo subclinico
A7: HCM | B7: 26 – 32 pg se baixo hipocromica: anemia por deficiencia ferro, talassemia hipercromica falta de B12 e B9
A8: CHCM | B8: 31,5 – 36,5 g/dL alto pode ser uma doença histerocitose, falciforme. Se der baixa pode ser anemia por falta de ferro, talassemia
A9: RDW | B9: 11% qd alto é por falta de hemacias, pode ser pq doou sangue se ta alto o corpo ta perdendo hemacias ou tem alguma doença roubando e se tiver baixo o corpo n ta produzindo a quantidade q deveria como anemia aplastica
A10: Leucócitos | B10: 5.000 – 6.500 mm3 acima de 6.500 já pensa em infecção cronica (viral ou bacteriana), disbiose e quando baixo de 4.000 é imunidade baixa, quem usa imunosupressor para doenças autoimunes ou alimentaçao mt restritiva
A11: Neutrófilo | B11: 45% - 55% qd baixo neutropenia pode ser por conta da quimioterapia ou após covi ou infecçao viral estresse aumenta neutrofilo imunidade inata (primeira linha de defesa)
A12: Linfócitos | B12: 25% - 35% qd baixo linfopenia pode ser infecçao viral, HIV e qd alto linfocitose tbm pode ser infcçao alta, mononucleose, hipertireoidismo imunidade adquirida (segunda linha de defesa)
A13: Eosinófilos | B13: Menor 1% é ótimo Até 2% é bom 2% - 4% disbiose ou reparo tecidual 5% - 7% hipersensibilidade tardia Maior que 7% parasitose intestinal, alergias. TH2 relacionado a alergias aumenta eosinofilo quando está em 0 que n produz nada pode ser infacçao cronica porem n se tem mts estudos
A14: Monócitos | B14: Abaixo de 8%
... A26: LDL colesterol | B26: Inferior a 100 mg/dL
A27: CT/HDL | B27: Abaixo de 3,3 | C27: =C23/C24 -> #DIV/0! | D27: =D23/D24 -> #DIV/0! | E27: =E23/E24 -> #DIV/0! | F27: =F23/F24 -> #DIV/0! | G27: =G23/G24 -> #DIV/0! | H27: =H23/H24 -> #DIV/0! | I27: =I23/I24 -> #DIV/0! | J27: =J23/J24 -> #DIV/0! | ... O27: =O23/O24 -> #DIV/0!
A28: LDL/HDL | B28: Abaixo de 2,3 | C28: =C26/C24 -> #DIV/0! | D28: =D26/D24 -> #DIV/0! | E28: =E26/E24 -> #DIV/0! | F28: =F26/F24 -> #DIV/0! | G28: =G26/G24 -> #DIV/0! | H28: =H26/H24 -> #DIV/0! | I28: =I26/I24 -> #DIV/0! | J28: =J26/J24 -> #DIV/0! | ... O28: =O26/O24 -> #DIV/0!
A29: TAG/HDL melhor preditor de saúde CV | B29: Abaixo de 2,5 Acima de 2,5 indica RI e DCV | C29: =C25/C24 -> #DIV/0! | D29: =D25/D24 -> #DIV/0! | E29: =E25/E24 -> #DIV/0! | F29: =F25/F24 -> #DIV/0! | G29: =G25/G24 -> #DIV/0! | H29: =H25/H24 -> #DIV/0! | I29: =I25/I24 -> #DIV/0! | J29: =J25/J24 -> #DIV/0! | ... O29: =O25/O24 -> #DIV/0!
A30: TGO/AST | B30: Abaixo de 20 U/L
A31: TGP/ALT | B31: Abaixo de 20 U/L
A32: AST/ALT divisão das enzimas | B32: ideal proximo a 1 se tiver mt alterada tem relação com esteatose hepatica e risco DCV e SIBO | C32: =C30/C31 -> #DIV/0!
A33: GGT (gama GT) | B33: Abaixo de 16 U/L
A34: Creatinina | B34: 0,6 – 1,2mg/dL
A35: Ureia sérica | B35: 10 – 45 mg/dL
A36: Microalbuminúria | B36: Até 30
A37: PCR us | B37: Abaixo 0,6 mg/L para prevenção de DCV Abaixo de 0,4 para câncer
A38: Homocisteína | B38: Abaixo de 10 µmol/L Se estiver alta pode ser excesso de consumo de carnes ou deficiência de complexo B ou polimorfismo MTHFR
A39: Fibrinogênio | B39: Abaixo de 300 mg/dL
A40: TSH ULTRA SENSÍVEL | B40: Acima de 0,5 mUI/ml Abaixo de 2,5 mUI/ml se abaixo de 0,5 risco de DCV, arritmia e infarto. 4,5 a 10 hipo subclinico TSH mt alto é hipo. Baixas calorias e cortisol alto tem relação com TSH alto. Suplementação de biotina, flavonoides e acido alfa lipoico alteram o examede TSH, tem q parar por dois dias para fazer o exame. Tem que parar de usar biotina por 72h antes do aexame, para n dar aletardo o TSH. PENSAR EM ZN, FE, SE, VIT A QUE SÃO COFATORES (suplementar) gestante menor 2,5 para n ter anormalidade fetal
A41: T4 livre | B41: 0,9 – 1,3 ng/dL
A42: T 3 livre | B42: 2,50 – 3,90 pg/mL ideal é de 2,7 - 3,25 T3 é a forma ativa
A43: T3L/T4L | B43: T3 dividido por T4 3 - 3,5 Se der abaixo o paciente pode sentir, frio, queda de cabelo, unhas fracas, dificuldade de perder peso, depressão, alergias... | C43: =C42/C41 -> #DIV/0!
A44: Anti-TG | B44: Negativo Se positivo HASHIMOTO Hipotireoidismo
A45: Anti-TPO | B45: Negativo Se positivo HASHIMOTO Hipotireoidismo Se o paciente tiver TPO alto e ainda defc. Ferro e hemoglobina baixa, tem q suplemnetar para amenizar o quadro de auto imunidade: ferro, magnésio, selenio, zinco e manganes.
A46: Anticorpo TRAB | B46: Negativo se positivo doença autoimune de GRAVES doença autoimune (hipertireoidismo) perda de peso rapida, tremorm insonia
A47: Anticorpo TSI | B47: Negativo se positivo doença autoimune de GRAVES doença autoimune (hipertireoidismo) perda de peso rapida, tremor, insonia
A48: Tireoglobulina | B48: 10-15 mCg/L marcador menos sensível de tireoide, pq pode estar alterada tbm em câncer
A49: Ferro sérico | B49: 30 – 160 mcg/dL
A50: Ferritina | B50: 70 – 150 Ferritina mt aumentada quer dizer que o paciente está com as membranas mais oxidadas, INFLAMAÇÃO Ferritina baixa leva a queda de cabelo, cansaço, falta de ar, mal funcionamento de tireoide
A51: Saturação de transferrina sérica (jejum) | B51: Normal = sem excesso de ferro. Maior que 45% e ferritina alta = hemocromatose hereditária
...

Sheet medidas
B1: Cálculos Pollock
B4: IDADE | C4: =#REF! -> #REF! | D4: =#REF! -> #REF! | E4: =#REF! -> #REF! | F4: =#REF! -> #REF! | G4: =#REF! -> #REF! | H4: =#REF! -> #REF! | I4: =#REF! -> #REF! | J4: =#REF! -> #REF!
B5: PESO | C5: =#REF! -> #REF! | D5: =#REF! -> #REF! | E5: =#REF! -> #REF! | F5: =#REF! -> #REF! | G5: =#REF! -> #REF! | H5: =#REF! -> #REF! | I5: =#REF! -> #REF! | J5: =#REF! -> #REF!
B6: Tríceps | C6: =#REF! -> #REF! | D6: =#REF! -> #REF! | E6: =#REF! -> #REF! | F6: =#REF! -> #REF! | G6: =#REF! -> #REF! | H6: =#REF! -> #REF! | I6: =#REF! -> #REF! | J6: =#REF! -> #REF!
B7: Peitoral | C7: =#REF! -> #REF! | D7: =#REF! -> #REF! | E7: =#REF! -> #REF! | F7: =#REF! -> #REF! | G7: =#REF! -> #REF! | H7: =#REF! -> #REF! | I7: =#REF! -> #REF! | J7: =#REF! -> #REF!
B8: Subescapular | C8: =#REF! -> #REF! | D8: =#REF! -> #REF! | E8: =#REF! -> #REF! | F8: =#REF! -> #REF! | G8: =#REF! -> #REF! | H8: =#REF! -> #REF! | I8: =#REF! -> #REF! | J8: =#REF! -> #REF!
B9: Supraíliaca | C9: =#REF! -> #REF! | D9: =#REF! -> #REF! | E9: =#REF! -> #REF! | F9: =#REF! -> #REF! | G9: =#REF! -> #REF! | H9: =#REF! -> #REF! | I9: =#REF! -> #REF! | J9: =#REF! -> #REF!
B10: Abdominal | C10: =#REF! -> #REF! | D10: =#REF! -> #REF! | E10: =#REF! -> #REF! | F10: =#REF! -> #REF! | G10: =#REF! -> #REF! | H10: =#REF! -> #REF! | I10: =#REF! -> #REF! | J10: =#REF! -> #REF!
B11: Coxa | C11: =#REF! -> #REF! | D11: =#REF! -> #REF! | E11: =#REF! -> #REF! | F11: =#REF! -> #REF! | G11: =#REF! -> #REF! | H11: =#REF! -> #REF! | I11: =#REF! -> #REF! | J11: =#REF! -> #REF!
B12: Panturrilha | C12: =#REF! -> #REF! | D12: =#REF! -> #REF! | E12: =#REF! -> #REF! | F12: =#REF! -> #REF! | G12: =#REF! -> #REF! | H12: =#REF! -> #REF! | I12: =#REF! -> #REF! | J12: =#REF! -> #REF!
B14: DC | C14: =SUM(C6:C12) -> #REF! | D14: =SUM(D6:D12) -> #REF! | E14: =SUM(E6:E12) -> #REF! | F14: =SUM(F6:F12) -> #REF! | G14: =SUM(G6:G12) -> #REF! | H14: =SUM(H6:H12) -> #REF! | I14: =SUM(I6:I12) -> #REF! | J14: =SUM(J6:J12) -> #REF!
B15: DC² | C15: =SUM(C14*C14) -> #REF! | D15: =SUM(D14*D14) -> #REF! | E15: =SUM(E14*E14) -> #REF! | F15: =SUM(F14*F14) -> #REF! | G15: =SUM(G14*G14) -> #REF! | H15: =SUM(H14*H14) -> #REF! | I15: =SUM(I14*I14) -> #REF! | J15: =SUM(J14*J14) -> #REF!
B16: 0,0004697 x DC | C16: =SUM(0.0004697*C14) -> #REF! | D16: =SUM(0.0004697*D14) -> #REF! | E16: =SUM(0.0004697*E14) -> #REF! | F16: =SUM(0.0004697*F14) -> #REF! | G16: =SUM(0.0004697*G14) -> #REF! | H16: =SUM(0.0004697*H14) -> #REF! | I16: =SUM(0.0004697*I14) -> #REF! | J16: =SUM(0.0004697*J14) -> #REF!
B17: 0,00000056 x DC² | C17: =SUM(0.00000056*C15) -> #REF! | D17: =SUM(0.00000056*D15) -> #REF! | E17: =SUM(0.00000056*E15) -> #REF! | F17: =SUM(0.00000056*F15) -> #REF! | G17: =SUM(0.00000056*G15) -> #REF! | H17: =SUM(0.00000056*H15) -> #REF! | I17: =SUM(0.00000056*I15) -> #REF! | J17: =SUM(0.00000056*J15) -> #REF!
B18: 0,00012828xI | C18: =SUM(C4*0.00012828) -> #REF! | D18: =SUM(D4*0.00012828) -> #REF! | E18: =SUM(E4*0.00012828) -> #REF! | F18: =SUM(F4*0.00012828) -> #REF! | G18: =SUM(G4*0.00012828) -> #REF! | H18: =SUM(H4*0.00012828) -> #REF! | I18: =SUM(I4*0.00012828) -> #REF! | J18: =SUM(J4*0.00012828) -> #REF!
B19: DENSIDADE | C19: =SUM(1.097-C16+C17-C18) -> #REF! | D19: =SUM(1.097-D16+D17-D18) -> #REF! | E19: =SUM(1.097-E16+E17-E18) -> #REF! | F19: =SUM(1.097-F16+F17-F18) -> #REF! | G19: =SUM(1.097-G16+G17-G18) -> #REF! | H19: =SUM(1.097-H16+H17-H18) -> #REF! | I19: =SUM(1.097-I16+I17-I18) -> #REF! | J19: =SUM(1.097-J16+J17-J18) -> #REF!
B20: CALCULOG | C20: =SUM(5.01/C19) -> #REF! | D20: =SUM(5.01/D19) -> #REF! | E20: =SUM(5.01/E19) -> #REF! | F20: =SUM(5.01/F19) -> #REF! | G20: =SUM(5.01/G19) -> #REF! | H20: =SUM(5.01/H19) -> #REF! | I20: =SUM(5.01/I19) -> #REF! | J20: =SUM(5.01/J19) -> #REF!
B21: %GORDURA | C21: =SUM(C20-4.57) -> #REF! | D21: =SUM(D20-4.57) -> #REF! | E21: =SUM(E20-4.57) -> #REF! | F21: =SUM(F20-4.57) -> #REF! | G21: =SUM(G20-4.57) -> #REF! | H21: =SUM(H20-4.57) -> #REF! | I21: =SUM(I20-4.57) -> #REF! | J21: =SUM(J20-4.57) -> #REF!
B22: - | C22: =SUM(C20-4.57) -> #REF! | D22: =SUM(D20-4.57) -> #REF! | E22: =SUM(E20-4.57) -> #REF! | F22: =SUM(F20-4.57) -> #REF! | G22: =SUM(G20-4.57) -> #REF! | H22: =SUM(H20-4.57) -> #REF! | I22: =SUM(I20-4.57) -> #REF! | J22: =SUM(J20-4.57) -> #REF!
B23: MASSA LIVRE | C23: =SUM(1-C22) -> #REF! | D23: =SUM(1-D22) -> #REF! | E23: =SUM(1-E22) -> #REF! | F23: =SUM(1-F22) -> #REF! | G23: =SUM(1-G22) -> #REF! | H23: =SUM(1-H22) -> #REF! | I23: =SUM(1-I22) -> #REF! | J23: =SUM(1-J22) -> #REF!
B24: GORDURA (kg) | C24: =SUM(C5-C25) -> #REF! | D24: =SUM(D5-D25) -> #REF! | E24: =SUM(E5-E25) -> #REF! | F24: =SUM(F5-F25) -> #REF! | G24: =SUM(G5-G25) -> #REF! | H24: =SUM(H5-H25) -> #REF! | I24: =SUM(I5-I25) -> #REF! | J24: =SUM(J5-J25) -> #REF!
B25: MLG (kg) | C25: =SUM(C5*C23) -> #REF! | D25: =SUM(D5*D23) -> #REF! | E25: =SUM(E5*E23) -> #REF! | F25: =SUM(F5*F23) -> #REF! | G25: =SUM(G5*G23) -> #REF! | H25: =SUM(H5*H23) -> #REF! | I25: =SUM(I5*I23) -> #REF! | J25: =SUM(J5*J23) -> #REF!

Sheet Hábitos alimentares
A1: HÁBITOS ALIMENTARES
A2: Consumo de água | B2: =QPC!Y2 -> 0
A3: Consumo de suco | B3: =QPC!AA2 -> 0
A4: Consumo refrigerantes | B4: =QPC!W2 -> 0
A5: Consumo de água de coco | B5: =QPC!AD2 -> 0
A6: Consumo de chás | B6: =QPC!AB2 -> 0
A7: Consumo de café
A8: Consumo de leite
A9: Queijo
A10: Iogurte
A11: Manteiga/margarina/requeijão
A12: Consumo de líquidos no almoço ou janta
A13: Açúcar
A14: Adoçante
A15: Sal
A16: Temperos naturais
A17: Temperos industrializados
A18: Balas e chicletes
... A24: Salgados fritos ou empanados
A25: Pizza, hambúrguer, lasanha e cachorro quente | B25: =QPC!AC2 -> 0
A26: Verduras e legumes
A27: Frutas
A28: Ovos
A29: Carnes
A30: Sardinha/atum
A31: Tapioca
A33: Mastigação
A34: Onde costuma realizar suas refeições
A35: Quem cozinha
A36: Microondas ou geladeira no serviço
A38: Necessidade de doce após almoço e jantar Resistência a insulina
A39: Necessidade de doce após as 17h da tarde Queda de serotonina
A40: Necessidade de doce da hora que acorda até a hora de dormir Síndrome fungica e disbiose
A42: Preferências alimentares: | B42: =QPC!U2 -> 0
A43: Aversões alimentares: | B43: =QPC!V2 -> 0
A45: INQUERITO ALIMENTAR - DIA USUAL
A46: Acorda ás:
A47: Primeira refeição do dia:
A52: Segunda refeição do dia:
A57: Terceira refeição do dia:
...

Sheet Antropometria
H6: Aline Peres de Souza
H7: Nutricionista Clínica Funcional
H8: CRN - 10 5614
B10: Altura cm: | L10: Meta:
B11: Data | C11: 1 | D11: 2 | E11: 3 | F11: 4 | G11: 5 | H11: 6 | I11: 7 | J11: 8 | K11: 9 | L11: Grandes mudanças!
B12: Peso
B13: IMC | C13: =Cálculos!K4 -> Aguarde
B14: Braço
B15: Cintura
B16: Abdômen
B17: D. Tríceps
B18: % gordura corporal
B19: % músculo esqueletico
B20: Metabolismo basal
B21: idade corporal
B22: Nível de gordura visceral

Sheet Cálculos
C2: =IF(#REF!="","",#REF!) -> #REF!
C4: ='Informações gerais'!B4 -> 0 | E4: =Antropometria!C12 -> 0 | G4: =Antropometria!D10 -> 0 | I4: Sedentário | K4: =IFERROR(E4/((G4/100)^2),"Aguarde") -> Aguarde | M4: =IF(K4="Aguarde","Aguarde",IF(K4<18.5,"Baixo Peso",IF(K4<24.9,"Eutrofia",IF(K4<29.9,"Sobrepeso","Obesidade")))) -> Aguarde
C5: Idade (anos) | E5: Peso (kg) | G5: Altura (cm) | I5: Atividade Fisica | K5: IMC (kg/m²) | M5: Classe (OMS)
C7: =IF(#REF!="","Aguarde",VLOOKUP(Cálculos!I4,Cálculos!AF101:AG105,2,FALSE)) -> #REF! | E7: =$G$13 -> 1912.75 | G7: =(I13*4)/E7 -> 0.18911515 | I7: =(K13*4)/E7 -> 0.26831525 | K7: =(M13*9)/E7 -> 0.5425696 | M7: =I13/E4 -> #DIV/0!
C8: kcal (EER) | E8: kcal (Plano) | G8: PTN (Plano) | I8: CHO (Plano) | K8: LIP (Plano) | M8: PTN (g/kg)
C10: Plano Alimentar
C12: Grupos | E12: Porções | G12: kcal | I12: PTN | K12: CHO | M12: LIP
C13: Totais | E13: =SUM(E16:E26) -> 21 | G13: =SUM(G16:G26) -> 1912.75 | I13: =SUM(I16:I26) -> 90.4325 | K13: =SUM(K16:K26) -> 128.305 | M13: =SUM(M16:M26) -> 115.31111
C15: Grupos | E15: Porções | G15: kcal | I15: PTN | K15: CHO | M15: LIP
C16: Cereal | E16: 2 | G16: =SUM(I16*4)+(K16*4)+(M16*9) -> 150 | I16: =(E16*1.6875) -> 3.375 | K16: =(E16*14.8125) -> 29.625 | M16: =E16*1 -> 2
C17: Fruta | E17: 3 | G17: =SUM(I17*4)+(K17*4)+(M17*9) -> 207 | I17: =E17*0.8625 -> 2.5875 | K17: =E17*15.0075 -> 45.0225 | M17: =E17*0.613333333333333 -> 1.84
C18: Fruta Suco | E18: 0 | G18: =SUM(I18*4)+(K18*4)+(M18*9) -> 0 | I18: =E18*0.7275 -> 0 | K18: =E18*22.5525 -> 0 | M18: =E18*0.431111111111111 -> 0
C19: Verdura | E19: 3 | G19: =SUM(I19*4)+(K19*4)+(M19*9) -> 57 | I19: =E19*0.8075 -> 2.4225 | K19: =E19*2.1375 -> 6.4125 | M19: =E19*0.802222222222222 -> 2.4066667
C20: Legume | E20: 3 | G20: =SUM(I20*4)+(K20*4)+(M20*9) -> 123 | I20: =E20*1.025 -> 3.075 | K20: =E20*6.15 -> 18.45 | M20: =E20*1.36666666666667 -> 4.1
C21: Leite integral | E21: 1 | G21: =SUM(I21*4)+(K21*4)+(M21*9) -> 157 | I21: =E21*8.635 -> 8.635 | K21: =E21*12.1675 -> 12.1675 | M21: =E21*8.19888888888889 -> 8.1988889
C22: Leite desnatado | E22: 0 | G22: =SUM(I22*4)+(K22*4)+(M22*9) -> 0 | I22: =E22*7.605 -> 0 | K22: =E22*11.505 -> 0 | M22: =E22*0.173333333333333 -> 0
C23: Queijo | E23: 1 | G23: =SUM(I23*4)+(K23*4)+(M23*9) -> 85 | I23: =E23*6.1625 -> 6.1625 | K23: =E23*0.6375 -> 0.6375 | M23: =E23*6.42222222222222 -> 6.4222222
C24: Leguminosa | E24: 1 | G24: =SUM(I24*4)+(K24*4)+(M24*9) -> 98 | I24: =E24*6.125 -> 6.125 | K24: =E24*14.7 -> 14.7 | M24: =E24*1.63333333333333 -> 1.6333333
C25: Carne | E25: 4 | G25: =SUM(I25*4)+(K25*4)+(M25*9) -> 516 | I25: =E25*14.5125 -> 58.05 | K25: =E25*0.3225 -> 1.29 | M25: =E25*7.74 -> 30.96
C26: Gordura | E26: 3 | G26: =SUM(I26*4)+(K26*4)+(M26*9) -> 519.75 | I26: 0 | K26: 0 | M26: =E26*19.25 -> 57.75
AH100: Homem | AJ100: Mulher
AA101: CAF | AB101: DB | AC101: P1 | AD101: P2 | AF101: EER | AG101: DB | AH101: P1 | AI101: P2 | AJ101: P1 | AK101: P2
AA102: Sedentário | AB102: =IF(OR($M$4="Baixo Peso",$M$4="Eutrofico"),AC102,AD102) -> 1 | AC102: 1 | AD102: 1 | AF102: Sedentário | AG102: =IF(#REF!=Cálculos!$AH$100,IF(OR(Cálculos!$M$4="Baixo Peso",Cálculos!$M$4="Eutrofia"),Cálculos!$AH102,Cálculos!$AI102),IF(OR(Cálculos!$M$4="Baixo Peso",Cálculos!$M$4="Eutrofia"),Cálculos!$AJ102,Cálculos!$AK102)) -> #REF! | AH102: =662-(9.53*$C$4)+$AC102*(15.91*$E$4+539.6*($G$4/100)) -> 662 | AI102: =1086-(10.4*$C$4)+$AD102*(13.7*$E$4+416*($G$4/100)) -> 1086 | AJ102: =354-(6.91*$C$4)+$AC102*(9.36*$E$4+726*($G$4/100)) -> 354 | AK102: =448-(7.95*$C$4)+$AD102*(11.4*$E$4+619*($G$4/100)) -> 448
AA103: Pouco Ativo | AB103: =IF(OR($M$4="Baixo Peso",$M$4="Eutrofico"),AC103,AD103) -> 1.14 | AC103: 1.11 | AD103: 1.14 | AF103: Pouco Ativo | AG103: =IF(OR($M$4="Baixo Peso",$M$4="Eutrofico"),AH103,AI103) -> 1086 | AH103: =662-(9.53*$C$4)+$AC103*(15.91*$E$4+539.6*($G$4/100)) -> 662 | AI103: =1086-(10.4*$C$4)+$AD103*(13.7*$E$4+416*($G$4/100)) -> 1086 | AJ103: =354-(6.91*$C$4)+$AC103*(9.36*$E$4+726*($G$4/100)) -> 354 | AK103: =448-(7.95*$C$4)+$AD103*(11.4*$E$4+619*($G$4/100)) -> 448
AA104: Ativo | AB104: =IF(OR($M$4="Baixo Peso",$M$4="Eutrofico"),AC104,AD104) -> 1.28 | AC104: 1.26 | AD104: 1.28 | AF104: Ativo | AG104: =IF(OR($M$4="Baixo Peso",$M$4="Eutrofico"),AH104,AI104) -> 1086 | AH104: =662-(9.53*$C$4)+$AC104*(15.91*$E$4+539.6*($G$4/100)) -> 662 | AI104: =1086-(10.4*$C$4)+$AD104*(13.7*$E$4+416*($G$4/100)) -> 1086 | AJ104: =354-(6.91*$C$4)+$AC104*(9.36*$E$4+726*($G$4/100)) -> 354 | AK104: =448-(7.95*$C$4)+$AD104*(11.4*$E$4+619*($G$4/100)) -> 448
AA105: Muito Ativo | AB105: =IF(OR($M$4="Baixo Peso",$M$4="Eutrofico"),AC105,AD105) -> 1.5 | AC105: 1.46 | AD105: 1.5 | AF105: Muito Ativo | AG105: =IF(OR($M$4="Baixo Peso",$M$4="Eutrofico"),AH105,AI105) -> 1086 | AH105: =662-(9.53*$C$4)+$AC105*(15.91*$E$4+539.6*($G$4/100)) -> 662 | AI105: =1086-(10.4*$C$4)+$AD105*(13.7*$E$4+416*($G$4/100)) -> 1086 | AJ105: =354-(6.91*$C$4)+$AC105*(9.36*$E$4+726*($G$4/100)) -> 354 | AK105: =448-(7.95*$C$4)+$AD105*(11.4*$E$4+619*($G$4/100)) -> 448

Sheet P1
H2: Plano Alimentar | N2: Paciente: | O2: =#REF! -> #REF! | S2: Data: | T2: =TODAY() -> 45937
D3: Nome: | I3: Data:
B5: Refeição | C5: Horário | D5: Grupo | E5: Porção | F5: Alimento | H5: Quantidade | I5: Medida Caseira
B6: Mantenha uma alimentação saudável e colorida!
B7: Café da manhã | C7: 0.33333333 | D7: CARBOIDRATO | E7: 2 | F7: Cookies sem glúten | H7: =IF(E7="-","-",VLOOKUP('P1'!F7,Porções!$B$1:$D$312,2,0)*E7) -> 8 | I7: =IF(E7="-","-",VLOOKUP('P1'!F7,Porções!$B$1:$D$312,3,0)) -> unidade(s)
D8: FRUTA | E8: 1 | F8: Banana | H8: 1 | I8: =IF(E8="-","-",VLOOKUP('P1'!F8,Porções!$B$1:$D$312,3,0)) -> unidade(s)
D9: PROTEÍNA | E9: 1 | F9: Ovo(s) cozido(s) | H9: 1 | I9: =IF(E9="-","-",VLOOKUP('P1'!F9,Porções!$B$1:$D$312,3,0)) -> unidade(s)
D10: PROTEÍNA | E10: 0.5 | F10: Queijo branco / ricota | H10: 1 | I10: =IF(E10="-","-",VLOOKUP('P1'!F10,Porções!$B$1:$D$312,3,0)) -> fatia grande
B11: "Inunde" seu corpo de vitaminas e minerais de 3 em 3 horas!
B12: Lanche da manhã | C12: 0.41666667 | D12: FRUTA | E12: 1 | F12: Pêra | H12: =IF(E12="-","-",VLOOKUP('P1'!F12,Porções!$B$1:$D$312,2,0)*E12) -> 1 | I12: =IF(E12="-","-",VLOOKUP('P1'!F12,Porções!$B$1:$D$312,3,0)) -> unidade(s)
B14: Almoço | C14: 0.52083333 | D14: PROTEÍNA | E14: 2 | F14: Frango grelhado | H14: =IF(E14="-","-",VLOOKUP('P1'!F14,Porções!$B$1:$D$312,2,0)*E14) -> 2 | I14: =IF(E14="-","-",VLOOKUP('P1'!F14,Porções!$B$1:$D$312,3,0)) -> pedaço(s) médio(s)
D15: VERDURA | E15: 2 | F15: Alface | H15: =IF(E15="-","-",VLOOKUP('P1'!F15,Porções!$B$1:$D$312,2,0)*E15) -> 2 | I15: =IF(E15="-","-",VLOOKUP('P1'!F15,Porções!$B$1:$D$312,3,0)) -> pires ou mais
D16: LEGUME | E16: 2 | F16: Beterraba | H16: =IF(E16="-","-",VLOOKUP('P1'!F16,Porções!$B$1:$D$312,2,0)*E16) -> 4 | I16: =IF(E16="-","-",VLOOKUP('P1'!F16,Porções!$B$1:$D$312,3,0)) -> colher(es) de sopa
D17: CARBOIDRATO | E17: 1 | F17: Arroz integral | H17: =IF(E17="-","-",VLOOKUP('P1'!F17,Porções!$B$1:$D$312,2,0)*E17) -> 1 | I17: =IF(E17="-","-",VLOOKUP('P1'!F17,Porções!$B$1:$D$312,3,0)) -> colher(es) de servir
B18: "Inunde" seu corpo de vitaminas e minerais de 3 em 3 horas!
B19: Lanche da noite | C19: 0.66666667 | D19: GORDURA | E19: 1 | F19: Castanha do pará | H19: =IF(E19="-","-",VLOOKUP('P1'!F19,Porções!$B$1:$D$312,2,0)*E19) -> 3 | I19: =IF(E19="-","-",VLOOKUP('P1'!F19,Porções!$B$1:$D$312,3,0)) -> unidade(s)
D20: FRUTA | E20: 1 | F20: Uva | H20: =IF(E20="-","-",VLOOKUP('P1'!F20,Porções!$B$1:$D$312,2,0)*E20) -> 10 | I20: =IF(E20="-","-",VLOOKUP('P1'!F20,Porções!$B$1:$D$312,3,0)) -> unidade(s)
B21: Lanche da noite | C21: 0.75 | D21: OUTROS | E21: 1 | F21: Canela | H21: =IF(E21="-","-",VLOOKUP('P1'!F21,Porções!$B$1:$D$312,2,0)*E21) -> 1 | I21: =IF(E21="-","-",VLOOKUP('P1'!F21,Porções!$B$1:$D$312,3,0)) -> pitada
D22: FRUTA | E22: 1 | F22: Banana | H22: =IF(E22="-","-",VLOOKUP('P1'!F22,Porções!$B$1:$D$312,2,0)*E22) -> 1 | I22: =IF(E22="-","-",VLOOKUP('P1'!F22,Porções!$B$1:$D$312,3,0)) -> unidade(s)
B23: Ceia | C23: 0.83333333 | D23: CARBOIDRATO | E23: 2 | F23: Macarrão penne/parafuso | H23: =IF(E23="-","-",VLOOKUP('P1'!F23,Porções!$B$1:$D$312,2,0)*E23) -> 3 | I23: =IF(E23="-","-",VLOOKUP('P1'!F23,Porções!$B$1:$D$312,3,0)) -> colher(es) de servir
D24: PROTEÍNA | E24: 1 | F24: Carne ou Frango | H24: =IF(E24="-","-",VLOOKUP('P1'!F24,Porções!$B$1:$D$312,2,0)*E24) -> 1 | I24: =IF(E24="-","-",VLOOKUP('P1'!F24,Porções!$B$1:$D$312,3,0)) -> pedaço(s) médio(s)
D25: VERDURA | E25: 1 | F25: Agrião | H25: =IF(E25="-","-",VLOOKUP('P1'!F25,Porções!$B$1:$D$312,2,0)*E25) -> 1 | I25: =IF(E25="-","-",VLOOKUP('P1'!F25,Porções!$B$1:$D$312,3,0)) -> pires ou mais
B26: >> Atente-se às orientações do seu plano alimentar <<
B28: Opções

Sheet Formulas
A1: Mantenha uma alimentação saudável e colorida!
A2: Beba pelo menos 2 litros de água por dia. Se necessário, carregue uma garrafinha com você. | C2: CARBOIDRATO
A3: "Inunde" seu corpo de vitaminas e minerais de 3 em 3 horas! | C3: VERDURA
A4: Restrinja o consumo de carne vermelha para no máximo 2 ou 3 vezes por semana. | C4: LEGUME
A5: Para aumentar a sensação de saciedade, coma primeiramente a salada e mastigue devagar! | C5: FRUTA
A6: Crie o hábito de ter uma rotina regular. Uma informação nutricional precisa faz bem à saúde! | C6: SUCO
A7: Varie a alimentação e alterne as opções de alimentos de acordo com a lista de substituições. | C7: °SUCO.LIGHT
A8: Manter uma boa alimentação é ideal para o fortalecimento do sistema imunológico! | C8: LEITE
A9: Uma alimentação balanceada permite a perda de peso saudável e definitiva. Coloque-a como prioridade na sua rotina. | C9: PASTASºPATÊS
C10: °LEITE.LIGHT
C11: °QUEIJO.LIGHT
C12: PROTEÍNA
C13: °CARNE.LANCHE
C14: LEGUMINOSA
C15: GORDURA
C16: SEMENTESºFARELOS
C17: OUTROS
C18: SUPLEMENTOS
C19: EVENTUAL
C20: -

Sheet Porções
B2: CARBOIDRATO | C2: Porções | D2: Medidas caseiras
B4: "Mabel" 100calorias/"eQlibri" cracker | C4: 0.66 | D4: pacotinho
B5: Amaranto em flocos | C5: 2 | D5: colher(es) de sopa
B6: Arroz | C6: 1 | D6: colher(es) de servir
B7: °Arroz | C7: 2 | D7: colher(es) de sopa
B8: Arroz branco/integral | C8: 2 | D8: colher(es) de sopa
B9: Arroz integral | C9: 1 | D9: colher(es) de servir
B10: Aveia | C10: 2 | D10: colher(es) de sopa
B11: Batata cozida | C11: 1 | D11: colher(es) de servir
B12: °Batata cozida | C12: 2 | D12: colher(es) de sopa
B13: Biscoito "Aveia e Mel" Nestlé | C13: 3 | D13: unidade(s)
B14: Biscoito "eQlibri" cracker | C14: 0.66 | D14: pacotinho (23g)
B15: Batata doce cozida | C15: 1 | D15: unidade(s) pequena(s)
... B64: Torrada wickbold | C64: 3 | D64: unidade(s)
B66: LEITE | C66: Porções | D66: Medidas caseiras
B68: Leite de arroz ou gergelim | C68: 1 | D68: copo(s) (200ml)
B69: Chia | C69: 2 | D69: colher(s) de sopa
B70: Coalhada | C70: 1 | D70: copo(s) (200ml)
B71: Iogurte ou leite | C71: 1 | D71: porção de 200 ml
B72: Leite de soja | C72: 1 | D72: copo(s) (200ml)
B73: Leite de vaca | C73: 1 | D73: copo(s) (200ml)
B74: Leite em pó | C74: 2 | D74: colher(s) de sopa
B75: Sollys | C75: 1 | D75: copo(s) (200ml)
B76: Soymilke | C76: 2 | D76: colher(s) de sopa
B77: Supra soy | C77: 2 | D77: colher(s) de sopa
B79: °LEITE.LIGHT | C79: Porções | D79: Medidas caseiras
B81: Ades Original | C81: 1 | D81: copo(s) (200ml)
B82: Coalhada light | C82: 1 | D82: copo(s) (200ml)
B83: Iogurte "Naturis" Soja | C83: 1 | D83: potinho
B84: Iogurte desnatado (± 75kcal) | C84: 1 | D84: potinho/garrafinha
B85: Iogurte light (± 75kcal) | C85: 1 | D85: potinho/garrafinha
B86: Leite desnatado | C86: 1 | D86: copo(s) (200ml)
B87: Leite em pó desnatado | C87: 2 | D87: colhe(es) de sopa
B88: Leite Zymil ou Sensy | C88: 1 | D88: copo(s) (200ml)
B89: Supra Soy sem lactose light | C89: 2 | D89: colhe(es) de sopa
B91: PASTASºPATÊS | C91: Porções | D91: Medidas caseiras
B93: Geléia sem açúcar | C93: 1 | D93: colher(s) de sopa
B94: Patês | C94: 1 | D94: colher(s) de sopa
B95: Pasta de tofu | C95: 1 | D95: colher(s) de sopa
B96: Tahine | C96: 1 | D96: colher(s) de sopa
...

Sheet Orientações

Sheet Ganho peso gest
A1: GESTANTE | B1: PESO PRÉ-GESTACIONAL | C1: ALTURA | E1: PESO TEÓRICO PRÉ-GESTACIONAL | F1: PESO ATUAL (PA1) | G1: GANHO DE PESO (GP1) | H1: TEMPO DE GESTAÇÃO (10-20) | I1: GANHO DE PESO TEÓRICO | J1: PESO ATUAL TEÓRICO | K1: PESO ATUAL (PA2) | L1: GANHO DE PESO (GP2) | M1: TEMPO DE GESTAÇÃO (20-30) | N1: GANHO DE PESO TEÓRICO | O1: PESO ATUAL TEÓRICO | P1: PESO ATUAL (PA2) | Q1: GANHO DE PESO (GP2) | R1: TEMPO DE GESTAÇÃO (>30) | S1: GANHO DE PESO TEÓRICO | T1: PESO ATUAL TEÓRICO | U1: GANHO TOTAL DE PESO
A2: MODELO | B2: 54 | D2: =POWER(C2,2) -> 0 | E2: =POWER(C2,2)*21 -> 0 | G2: =(F2-B2) -> -54 | I2: =(H2-10)*0.335 -> -3.35 | J2: =B2+I2 -> 50.65 | L2: =(K2-F2) -> 0 | N2: =(M2-20)*0.45 -> -9 | O2: =J2+N2 -> 41.65 | Q2: =(P2-K2) -> 0 | S2: =(R2-20)*0.4 -> -8 | T2: =O2+S2 -> 33.65 | U2: =P2-B2 -> -54
D3: =POWER(C3,2) -> 0 | E3: =POWER(C3,2)*21 -> 0 | G3: =(F3-B3) -> 0 | I3: =(H3-10)*0.335 -> -3.35 | J3: =B3+I3 -> -3.35 | L3: =(K3-F3) -> 0 | N3: =(M3-20)*0.45 -> -9 | O3: =J3+N3 -> -12.35 | Q3: =(P3-K3) -> 0 | S3: =(R3-20)*0.4 -> -8 | T3: =O3+S3 -> -20.35 | U3: =P3-B3 -> 0
D4: =POWER(C4,2) -> 0 | E4: =POWER(C4,2)*21 -> 0 | G4: =(F4-B4) -> 0 | I4: =(H4-10)*0.335 -> -3.35 | J4: =B4+I4 -> -3.35 | L4: =(K4-F4) -> 0 | N4: =(M4-20)*0.45 -> -9 | O4: =J4+N4 -> -12.35 | Q4: =(P4-K4) -> 0 | S4: =(R4-20)*0.4 -> -8 | T4: =O4+S4 -> -20.35 | U4: =P4-B4 -> 0
D5: =POWER(C5,2) -> 0 | E5: =POWER(C5,2)*21 -> 0 | G5: =(F5-B5) -> 0 | I5: =(H5-10)*0.335 -> -3.35 | J5: =B5+I5 -> -3.35 | L5: =(K5-F5) -> 0 | N5: =(M5-20)*0.45 -> -9 | O5: =J5+N5 -> -12.35 | Q5: =(P5-K5) -> 0 | S5: =(R5-20)*0.4 -> -8 | T5: =O5+S5 -> -20.35 | U5: =P5-B5 -> 0
D6: =POWER(C6,2) -> 0 | E6: =POWER(C6,2)*21 -> 0 | G6: =(F6-B6) -> 0 | I6: =(H6-10)*0.335 -> -3.35 | J6: =B6+I6 -> -3.35 | L6: =(K6-F6) -> 0 | N6: =(M6-20)*0.45 -> -9 | O6: =J6+N6 -> -12.35 | Q6: =(P6-K6) -> 0 | S6: =(R6-20)*0.4 -> -8 | T6: =O6+S6 -> -20.35 | U6: =P6-B6 -> 0
D7: =POWER(C7,2) -> 0 | E7: =POWER(C7,2)*21 -> 0 | G7: =(F7-B7) -> 0 | I7: =(H7-10)*0.335 -> -3.35 | J7: =B7+I7 -> -3.35 | L7: =(K7-F7) -> 0 | N7: =(M7-20)*0.45 -> -9 | O7: =J7+N7 -> -12.35 | Q7: =(P7-K7) -> 0 | S7: =(R7-20)*0.4 -> -8 | T7: =O7+S7 -> -20.35 | U7: =P7-B7 -> 0
D8: =POWER(C8,2) -> 0 | E8: =POWER(C8,2)*21 -> 0 | G8: =(F8-B8) -> 0 | I8: =(H8-10)*0.335 -> -3.35 | J8: =B8+I8 -> -3.35 | L8: =(K8-F8) -> 0 | N8: =(M8-20)*0.45 -> -9 | O8: =J8+N8 -> -12.35 | Q8: =(P8-K8) -> 0 | S8: =(R8-20)*0.4 -> -8 | T8: =O8+S8 -> -20.35 | U8: =P8-B8 -> 0
D9: =POWER(C9,2) -> 0 | E9: =POWER(C9,2)*21 -> 0 | G9: =(F9-B9) -> 0 | I9: =(H9-10)*0.335 -> -3.35 | J9: =B9+I9 -> -3.35 | L9: =(K9-F9) -> 0 | N9: =(M9-20)*0.45 -> -9 | O9: =J9+N9 -> -12.35 | Q9: =(P9-K9) -> 0 | S9: =(R9-20)*0.4 -> -8 | T9: =O9+S9 -> -20.35 | U9: =P9-B9 -> 0
D10: =POWER(C10,2) -> 0 | E10: =POWER(C10,2)*21 -> 0 | G10: =(F10-B10) -> 0 | I10: =(H10-10)*0.335 -> -3.35 | J10: =B10+I10 -> -3.35 | L10: =(K10-F10) -> 0 | N10: =(M10-20)*0.45 -> -9 | O10: =J10+N10 -> -12.35 | Q10: =(P10-K10) -> 0 | S10: =(R10-20)*0.4 -> -8 | T10: =O10+S10 -> -20.35 | U10: =P10-B10 -> 0
D11: =POWER(C11,2) -> 0 | E11: =POWER(C11,2)*21 -> 0 | G11: =(F11-B11) -> 0 | I11: =(H11-10)*0.335 -> -3.35 | J11: =B11+I11 -> -3.35 | L11: =(K11-F11) -> 0 | N11: =(M11-20)*0.45 -> -9 | O11: =J11+N11 -> -12.35 | Q11: =(P11-K11) -> 0 | S11: =(R11-20)*0.4 -> -8 | T11: =O11+S11 -> -20.35 | U11: =P11-B11 -> 0
D12: =POWER(C12,2) -> 0 | E12: =POWER(C12,2)*21 -> 0 | G12: =(F12-B12) -> 0 | I12: =(H12-10)*0.335 -> -3.35 | J12: =B12+I12 -> -3.35 | L12: =(K12-F12) -> 0 | N12: =(M12-20)*0.45 -> -9 | O12: =J12+N12 -> -12.35 | Q12: =(P12-K12) -> 0 | S12: =(R12-20)*0.4 -> -8 | T12: =O12+S12 -> -20.35 | U12: =P12-B12 -> 0
D13: =POWER(C13,2) -> 0 | E13: =POWER(C13,2)*21 -> 0 | G13: =(F13-B13) -> 0 | I13: =(H13-10)*0.335 -> -3.35 | J13: =B13+I13 -> -3.35 | L13: =(K13-F13) -> 0 | N13: =(M13-20)*0.45 -> -9 | O13: =J13+N13 -> -12.35 | Q13: =(P13-K13) -> 0 | S13: =(R13-20)*0.4 -> -8 | T13: =O13+S13 -> -20.35 | U13: =P13-B13 -> 0
D14: =POWER(C14,2) -> 0 | E14: =POWER(C14,2)*21 -> 0 | G14: =(F14-B14) -> 0 | I14: =(H14-10)*0.335 -> -3.35 | J14: =B14+I14 -> -3.35 | L14: =(K14-F14) -> 0 | N14: =(M14-20)*0.45 -> -9 | O14: =J14+N14 -> -12.35 | Q14: =(P14-K14) -> 0 | S14: =(R14-20)*0.4 -> -8 | T14: =O14+S14 -> -20.35 | U14: =P14-B14 -> 0
D15: =POWER(C15,2) -> 0 | E15: =POWER(C15,2)*21 -> 0 | G15: =(F15-B15) -> 0 | I15: =(H15-10)*0.335 -> -3.35 | J15: =B15+I15 -> -3.35 | L15: =(K15-F15) -> 0 | N15: =(M15-20)*0.45 -> -9 | O15: =J15+N15 -> -12.35 | Q15: =(P15-K15) -> 0 | S15: =(R15-20)*0.4 -> -8 | T15: =O15+S15 -> -20.35 | U15: =P15-B15 -> 0
A17: SEMANAS | B17: GRAMAS POR SEMANA
A18: 10ª - 20ª | B18: 335g/sem.(3500kg)
A19: 20ª - 30ª | B19: 450g/sem.(4500kg)
A20: 30ª sem. em diante | B20: 400g/sem.(4000kg)
I21: 1º trimestre | J21: 2º trimestre | K21: 3º trimestre
H22: peso atual | I22: =F2 -> 0 | J22: =K2 -> 0 | K22: =P2 -> 0
H23: peso esperado | I23: =J2 -> 50.65 | J23: =O2 -> 41.65 | K23: =T2 -> 33.65
